2021-03-30 21:33:30,097 ERROR: Exception on /auth/login [GET] [in /home/sora8d/Documents/AllVENV/FAIF/lib/python3.9/site-packages/flask/app.py:1891]
Traceback (most recent call last):
  File "/home/sora8d/Documents/AllVENV/FAIF/lib/python3.9/site-packages/flask/app.py", line 2447, in wsgi_app
    response = self.full_dispatch_request()
  File "/home/sora8d/Documents/AllVENV/FAIF/lib/python3.9/site-packages/flask/app.py", line 1952, in full_dispatch_request
    rv = self.handle_user_exception(e)
  File "/home/sora8d/Documents/AllVENV/FAIF/lib/python3.9/site-packages/flask/app.py", line 1821, in handle_user_exception
    reraise(exc_type, exc_value, tb)
  File "/home/sora8d/Documents/AllVENV/FAIF/lib/python3.9/site-packages/flask/_compat.py", line 39, in reraise
    raise value
  File "/home/sora8d/Documents/AllVENV/FAIF/lib/python3.9/site-packages/flask/app.py", line 1950, in full_dispatch_request
    rv = self.dispatch_request()
  File "/home/sora8d/Documents/AllVENV/FAIF/lib/python3.9/site-packages/flask/app.py", line 1936, in dispatch_request
    return self.view_functions[rule.endpoint](**req.view_args)
  File "/home/sora8d/Documents/Code/FAIF/application/auth/routes.py", line 29, in loginn
    return render_template("login.html", title="Sign in", form=form)
  File "/home/sora8d/Documents/AllVENV/FAIF/lib/python3.9/site-packages/flask/templating.py", line 138, in render_template
    ctx.app.jinja_env.get_or_select_template(template_name_or_list),
  File "/home/sora8d/Documents/AllVENV/FAIF/lib/python3.9/site-packages/jinja2/environment.py", line 930, in get_or_select_template
    return self.get_template(template_name_or_list, parent, globals)
  File "/home/sora8d/Documents/AllVENV/FAIF/lib/python3.9/site-packages/jinja2/environment.py", line 883, in get_template
    return self._load_template(name, self.make_globals(globals))
  File "/home/sora8d/Documents/AllVENV/FAIF/lib/python3.9/site-packages/jinja2/environment.py", line 857, in _load_template
    template = self.loader.load(self, name, globals)
  File "/home/sora8d/Documents/AllVENV/FAIF/lib/python3.9/site-packages/jinja2/loaders.py", line 115, in load
    source, filename, uptodate = self.get_source(environment, name)
  File "/home/sora8d/Documents/AllVENV/FAIF/lib/python3.9/site-packages/flask/templating.py", line 60, in get_source
    return self._get_source_fast(environment, template)
  File "/home/sora8d/Documents/AllVENV/FAIF/lib/python3.9/site-packages/flask/templating.py", line 89, in _get_source_fast
    raise TemplateNotFound(template)
jinja2.exceptions.TemplateNotFound: login.html
2021-03-30 21:34:27,855 INFO: Ya Server startup [in /home/sora8d/Documents/Code/FAIF/application/__init__.py:74]
2021-03-30 21:34:29,989 ERROR: Exception on /auth/login [GET] [in /home/sora8d/Documents/AllVENV/FAIF/lib/python3.9/site-packages/flask/app.py:1891]
Traceback (most recent call last):
  File "/home/sora8d/Documents/AllVENV/FAIF/lib/python3.9/site-packages/flask/app.py", line 2447, in wsgi_app
    response = self.full_dispatch_request()
  File "/home/sora8d/Documents/AllVENV/FAIF/lib/python3.9/site-packages/flask/app.py", line 1952, in full_dispatch_request
    rv = self.handle_user_exception(e)
  File "/home/sora8d/Documents/AllVENV/FAIF/lib/python3.9/site-packages/flask/app.py", line 1821, in handle_user_exception
    reraise(exc_type, exc_value, tb)
  File "/home/sora8d/Documents/AllVENV/FAIF/lib/python3.9/site-packages/flask/_compat.py", line 39, in reraise
    raise value
  File "/home/sora8d/Documents/AllVENV/FAIF/lib/python3.9/site-packages/flask/app.py", line 1950, in full_dispatch_request
    rv = self.dispatch_request()
  File "/home/sora8d/Documents/AllVENV/FAIF/lib/python3.9/site-packages/flask/app.py", line 1936, in dispatch_request
    return self.view_functions[rule.endpoint](**req.view_args)
  File "/home/sora8d/Documents/Code/FAIF/application/auth/routes.py", line 29, in loginn
    return render_template("auth/login.html", title="Sign in", form=form)
  File "/home/sora8d/Documents/AllVENV/FAIF/lib/python3.9/site-packages/flask/templating.py", line 137, in render_template
    return _render(
  File "/home/sora8d/Documents/AllVENV/FAIF/lib/python3.9/site-packages/flask/templating.py", line 120, in _render
    rv = template.render(context)
  File "/home/sora8d/Documents/AllVENV/FAIF/lib/python3.9/site-packages/jinja2/environment.py", line 1090, in render
    self.environment.handle_exception()
  File "/home/sora8d/Documents/AllVENV/FAIF/lib/python3.9/site-packages/jinja2/environment.py", line 832, in handle_exception
    reraise(*rewrite_traceback_stack(source=source))
  File "/home/sora8d/Documents/AllVENV/FAIF/lib/python3.9/site-packages/jinja2/_compat.py", line 28, in reraise
    raise value.with_traceback(tb)
  File "/home/sora8d/Documents/Code/FAIF/application/templates/auth/login.html", line 1, in top-level template code
    {% extends "T1.html" %}
  File "/home/sora8d/Documents/Code/FAIF/application/templates/T1.html", line 47, in top-level template code
    {% block content %}{% endblock %}
  File "/home/sora8d/Documents/Code/FAIF/application/templates/auth/login.html", line 25, in block "content"
    <p>New User? <a href="{{ url_for('register') }}">Click here u wannabe</a></p>
  File "/home/sora8d/Documents/AllVENV/FAIF/lib/python3.9/site-packages/flask/helpers.py", line 370, in url_for
    return appctx.app.handle_url_build_error(error, endpoint, values)
  File "/home/sora8d/Documents/AllVENV/FAIF/lib/python3.9/site-packages/flask/app.py", line 2216, in handle_url_build_error
    reraise(exc_type, exc_value, tb)
  File "/home/sora8d/Documents/AllVENV/FAIF/lib/python3.9/site-packages/flask/_compat.py", line 39, in reraise
    raise value
  File "/home/sora8d/Documents/AllVENV/FAIF/lib/python3.9/site-packages/flask/helpers.py", line 357, in url_for
    rv = url_adapter.build(
  File "/home/sora8d/Documents/AllVENV/FAIF/lib/python3.9/site-packages/werkzeug/routing.py", line 2179, in build
    raise BuildError(endpoint, values, method, self)
werkzeug.routing.BuildError: Could not build url for endpoint 'register'. Did you mean 'main.register' instead?
2021-03-30 21:35:13,731 INFO: Ya Server startup [in /home/sora8d/Documents/Code/FAIF/application/__init__.py:74]
2021-03-30 21:35:16,143 ERROR: Exception on /auth/login [GET] [in /home/sora8d/Documents/AllVENV/FAIF/lib/python3.9/site-packages/flask/app.py:1891]
Traceback (most recent call last):
  File "/home/sora8d/Documents/AllVENV/FAIF/lib/python3.9/site-packages/flask/app.py", line 2447, in wsgi_app
    response = self.full_dispatch_request()
  File "/home/sora8d/Documents/AllVENV/FAIF/lib/python3.9/site-packages/flask/app.py", line 1952, in full_dispatch_request
    rv = self.handle_user_exception(e)
  File "/home/sora8d/Documents/AllVENV/FAIF/lib/python3.9/site-packages/flask/app.py", line 1821, in handle_user_exception
    reraise(exc_type, exc_value, tb)
  File "/home/sora8d/Documents/AllVENV/FAIF/lib/python3.9/site-packages/flask/_compat.py", line 39, in reraise
    raise value
  File "/home/sora8d/Documents/AllVENV/FAIF/lib/python3.9/site-packages/flask/app.py", line 1950, in full_dispatch_request
    rv = self.dispatch_request()
  File "/home/sora8d/Documents/AllVENV/FAIF/lib/python3.9/site-packages/flask/app.py", line 1936, in dispatch_request
    return self.view_functions[rule.endpoint](**req.view_args)
  File "/home/sora8d/Documents/Code/FAIF/application/auth/routes.py", line 29, in loginn
    return render_template("auth/login.html", title="Sign in", form=form)
  File "/home/sora8d/Documents/AllVENV/FAIF/lib/python3.9/site-packages/flask/templating.py", line 137, in render_template
    return _render(
  File "/home/sora8d/Documents/AllVENV/FAIF/lib/python3.9/site-packages/flask/templating.py", line 120, in _render
    rv = template.render(context)
  File "/home/sora8d/Documents/AllVENV/FAIF/lib/python3.9/site-packages/jinja2/environment.py", line 1090, in render
    self.environment.handle_exception()
  File "/home/sora8d/Documents/AllVENV/FAIF/lib/python3.9/site-packages/jinja2/environment.py", line 832, in handle_exception
    reraise(*rewrite_traceback_stack(source=source))
  File "/home/sora8d/Documents/AllVENV/FAIF/lib/python3.9/site-packages/jinja2/_compat.py", line 28, in reraise
    raise value.with_traceback(tb)
  File "/home/sora8d/Documents/Code/FAIF/application/templates/auth/login.html", line 1, in top-level template code
    {% extends "T1.html" %}
  File "/home/sora8d/Documents/Code/FAIF/application/templates/T1.html", line 47, in top-level template code
    {% block content %}{% endblock %}
  File "/home/sora8d/Documents/Code/FAIF/application/templates/auth/login.html", line 25, in block "content"
    <p>New User? <a href="{{ url_for('auth.register') }}">Click here u wannabe</a></p>
  File "/home/sora8d/Documents/AllVENV/FAIF/lib/python3.9/site-packages/flask/helpers.py", line 370, in url_for
    return appctx.app.handle_url_build_error(error, endpoint, values)
  File "/home/sora8d/Documents/AllVENV/FAIF/lib/python3.9/site-packages/flask/app.py", line 2216, in handle_url_build_error
    reraise(exc_type, exc_value, tb)
  File "/home/sora8d/Documents/AllVENV/FAIF/lib/python3.9/site-packages/flask/_compat.py", line 39, in reraise
    raise value
  File "/home/sora8d/Documents/AllVENV/FAIF/lib/python3.9/site-packages/flask/helpers.py", line 357, in url_for
    rv = url_adapter.build(
  File "/home/sora8d/Documents/AllVENV/FAIF/lib/python3.9/site-packages/werkzeug/routing.py", line 2179, in build
    raise BuildError(endpoint, values, method, self)
werkzeug.routing.BuildError: Could not build url for endpoint 'auth.register'. Did you mean 'main.register' instead?
2021-03-30 21:35:34,283 INFO: Ya Server startup [in /home/sora8d/Documents/Code/FAIF/application/__init__.py:74]
