2021-04-02 18:22:09,631 INFO: Ya Server startup [in /home/sora8d/Documents/Code/FAIF/application/__init__.py:74]
2021-04-02 18:24:10,804 INFO: Ya Server startup [in /home/sora8d/Documents/Code/FAIF/application/__init__.py:74]
2021-04-02 18:24:49,627 INFO: Ya Server startup [in /home/sora8d/Documents/Code/FAIF/application/__init__.py:74]
2021-04-02 18:25:06,278 INFO: Ya Server startup [in /home/sora8d/Documents/Code/FAIF/application/__init__.py:74]
2021-04-02 18:28:03,982 INFO: Ya Server startup [in /home/sora8d/Documents/Code/FAIF/application/__init__.py:74]
2021-04-02 18:42:45,587 INFO: Ya Server startup [in /home/sora8d/Documents/Code/FAIF/application/__init__.py:74]
2021-04-02 18:44:37,418 INFO: Ya Server startup [in /home/sora8d/Documents/Code/FAIF/application/__init__.py:74]
2021-04-02 18:49:47,502 INFO: Ya Server startup [in /home/sora8d/Documents/Code/FAIF/application/__init__.py:74]
2021-04-02 18:52:10,451 INFO: Ya Server startup [in /home/sora8d/Documents/Code/FAIF/application/__init__.py:74]
2021-04-02 18:56:35,051 INFO: Ya Server startup [in /home/sora8d/Documents/Code/FAIF/application/__init__.py:74]
2021-04-02 19:37:33,166 INFO: Ya Server startup [in /home/sora8d/Documents/Code/FAIF/application/__init__.py:74]
2021-04-02 19:38:46,947 ERROR: Exception on /user/Miguel2 [GET] [in /home/sora8d/Documents/AllVENV/FAIF/lib/python3.9/site-packages/flask/app.py:1891]
Traceback (most recent call last):
  File "/home/sora8d/Documents/AllVENV/FAIF/lib/python3.9/site-packages/flask/app.py", line 2447, in wsgi_app
    response = self.full_dispatch_request()
  File "/home/sora8d/Documents/AllVENV/FAIF/lib/python3.9/site-packages/flask/app.py", line 1952, in full_dispatch_request
    rv = self.handle_user_exception(e)
  File "/home/sora8d/Documents/AllVENV/FAIF/lib/python3.9/site-packages/flask/app.py", line 1821, in handle_user_exception
    reraise(exc_type, exc_value, tb)
  File "/home/sora8d/Documents/AllVENV/FAIF/lib/python3.9/site-packages/flask/_compat.py", line 39, in reraise
    raise value
  File "/home/sora8d/Documents/AllVENV/FAIF/lib/python3.9/site-packages/flask/app.py", line 1950, in full_dispatch_request
    rv = self.dispatch_request()
  File "/home/sora8d/Documents/AllVENV/FAIF/lib/python3.9/site-packages/flask/app.py", line 1936, in dispatch_request
    return self.view_functions[rule.endpoint](**req.view_args)
  File "/home/sora8d/Documents/Code/FAIF/application/main/routes.py", line 79, in user
    return render_template('user.html', user=user, posts=posts, form=form, next_url=next_url, prev_url=prev_url)
  File "/home/sora8d/Documents/AllVENV/FAIF/lib/python3.9/site-packages/flask/templating.py", line 137, in render_template
    return _render(
  File "/home/sora8d/Documents/AllVENV/FAIF/lib/python3.9/site-packages/flask/templating.py", line 120, in _render
    rv = template.render(context)
  File "/home/sora8d/Documents/AllVENV/FAIF/lib/python3.9/site-packages/jinja2/environment.py", line 1090, in render
    self.environment.handle_exception()
  File "/home/sora8d/Documents/AllVENV/FAIF/lib/python3.9/site-packages/jinja2/environment.py", line 832, in handle_exception
    reraise(*rewrite_traceback_stack(source=source))
  File "/home/sora8d/Documents/AllVENV/FAIF/lib/python3.9/site-packages/jinja2/_compat.py", line 28, in reraise
    raise value.with_traceback(tb)
  File "/home/sora8d/Documents/Code/FAIF/application/templates/user.html", line 1, in top-level template code
    {% extends "T1.html" %}
  File "/home/sora8d/Documents/Code/FAIF/application/templates/T1.html", line 48, in top-level template code
    {% block content %}{% endblock %}
  File "/home/sora8d/Documents/Code/FAIF/application/templates/user.html", line 26, in block "content"
    <form action="{{ url_for('messages.chattomg', username=user.username) }}" method="post">
  File "/home/sora8d/Documents/AllVENV/FAIF/lib/python3.9/site-packages/flask/helpers.py", line 370, in url_for
    return appctx.app.handle_url_build_error(error, endpoint, values)
  File "/home/sora8d/Documents/AllVENV/FAIF/lib/python3.9/site-packages/flask/app.py", line 2216, in handle_url_build_error
    reraise(exc_type, exc_value, tb)
  File "/home/sora8d/Documents/AllVENV/FAIF/lib/python3.9/site-packages/flask/_compat.py", line 39, in reraise
    raise value
  File "/home/sora8d/Documents/AllVENV/FAIF/lib/python3.9/site-packages/flask/helpers.py", line 357, in url_for
    rv = url_adapter.build(
  File "/home/sora8d/Documents/AllVENV/FAIF/lib/python3.9/site-packages/werkzeug/routing.py", line 2179, in build
    raise BuildError(endpoint, values, method, self)
werkzeug.routing.BuildError: Could not build url for endpoint 'messages.chattomg' with values ['username']. Did you mean 'main.secret' instead?
2021-04-02 19:41:48,059 INFO: Ya Server startup [in /home/sora8d/Documents/Code/FAIF/application/__init__.py:76]
2021-04-02 19:41:57,771 ERROR: Exception on /user/FuckMe [GET] [in /home/sora8d/Documents/AllVENV/FAIF/lib/python3.9/site-packages/flask/app.py:1891]
Traceback (most recent call last):
  File "/home/sora8d/Documents/AllVENV/FAIF/lib/python3.9/site-packages/flask/app.py", line 2447, in wsgi_app
    response = self.full_dispatch_request()
  File "/home/sora8d/Documents/AllVENV/FAIF/lib/python3.9/site-packages/flask/app.py", line 1952, in full_dispatch_request
    rv = self.handle_user_exception(e)
  File "/home/sora8d/Documents/AllVENV/FAIF/lib/python3.9/site-packages/flask/app.py", line 1821, in handle_user_exception
    reraise(exc_type, exc_value, tb)
  File "/home/sora8d/Documents/AllVENV/FAIF/lib/python3.9/site-packages/flask/_compat.py", line 39, in reraise
    raise value
  File "/home/sora8d/Documents/AllVENV/FAIF/lib/python3.9/site-packages/flask/app.py", line 1950, in full_dispatch_request
    rv = self.dispatch_request()
  File "/home/sora8d/Documents/AllVENV/FAIF/lib/python3.9/site-packages/flask/app.py", line 1936, in dispatch_request
    return self.view_functions[rule.endpoint](**req.view_args)
  File "/home/sora8d/Documents/Code/FAIF/application/main/routes.py", line 79, in user
    return render_template('user.html', user=user, posts=posts, form=form, next_url=next_url, prev_url=prev_url)
  File "/home/sora8d/Documents/AllVENV/FAIF/lib/python3.9/site-packages/flask/templating.py", line 137, in render_template
    return _render(
  File "/home/sora8d/Documents/AllVENV/FAIF/lib/python3.9/site-packages/flask/templating.py", line 120, in _render
    rv = template.render(context)
  File "/home/sora8d/Documents/AllVENV/FAIF/lib/python3.9/site-packages/jinja2/environment.py", line 1090, in render
    self.environment.handle_exception()
  File "/home/sora8d/Documents/AllVENV/FAIF/lib/python3.9/site-packages/jinja2/environment.py", line 832, in handle_exception
    reraise(*rewrite_traceback_stack(source=source))
  File "/home/sora8d/Documents/AllVENV/FAIF/lib/python3.9/site-packages/jinja2/_compat.py", line 28, in reraise
    raise value.with_traceback(tb)
  File "/home/sora8d/Documents/Code/FAIF/application/templates/user.html", line 1, in top-level template code
    {% extends "T1.html" %}
  File "/home/sora8d/Documents/Code/FAIF/application/templates/T1.html", line 48, in top-level template code
    {% block content %}{% endblock %}
  File "/home/sora8d/Documents/Code/FAIF/application/templates/user.html", line 27, in block "content"
    <form action="{{ url_for('messages.chattomg', username=user.username) }}" method="post">
  File "/home/sora8d/Documents/AllVENV/FAIF/lib/python3.9/site-packages/flask/helpers.py", line 370, in url_for
    return appctx.app.handle_url_build_error(error, endpoint, values)
  File "/home/sora8d/Documents/AllVENV/FAIF/lib/python3.9/site-packages/flask/app.py", line 2216, in handle_url_build_error
    reraise(exc_type, exc_value, tb)
  File "/home/sora8d/Documents/AllVENV/FAIF/lib/python3.9/site-packages/flask/_compat.py", line 39, in reraise
    raise value
  File "/home/sora8d/Documents/AllVENV/FAIF/lib/python3.9/site-packages/flask/helpers.py", line 357, in url_for
    rv = url_adapter.build(
  File "/home/sora8d/Documents/AllVENV/FAIF/lib/python3.9/site-packages/werkzeug/routing.py", line 2179, in build
    raise BuildError(endpoint, values, method, self)
werkzeug.routing.BuildError: Could not build url for endpoint 'messages.chattomg' with values ['username']. Did you mean 'messages.messaging' instead?
2021-04-02 19:42:37,309 INFO: Ya Server startup [in /home/sora8d/Documents/Code/FAIF/application/__init__.py:76]
2021-04-02 19:42:50,851 ERROR: Exception on /user/FuckMe/chattomg [POST] [in /home/sora8d/Documents/AllVENV/FAIF/lib/python3.9/site-packages/flask/app.py:1891]
Traceback (most recent call last):
  File "/home/sora8d/Documents/AllVENV/FAIF/lib/python3.9/site-packages/flask/app.py", line 2447, in wsgi_app
    response = self.full_dispatch_request()
  File "/home/sora8d/Documents/AllVENV/FAIF/lib/python3.9/site-packages/flask/app.py", line 1952, in full_dispatch_request
    rv = self.handle_user_exception(e)
  File "/home/sora8d/Documents/AllVENV/FAIF/lib/python3.9/site-packages/flask/app.py", line 1821, in handle_user_exception
    reraise(exc_type, exc_value, tb)
  File "/home/sora8d/Documents/AllVENV/FAIF/lib/python3.9/site-packages/flask/_compat.py", line 39, in reraise
    raise value
  File "/home/sora8d/Documents/AllVENV/FAIF/lib/python3.9/site-packages/flask/app.py", line 1950, in full_dispatch_request
    rv = self.dispatch_request()
  File "/home/sora8d/Documents/AllVENV/FAIF/lib/python3.9/site-packages/flask/app.py", line 1936, in dispatch_request
    return self.view_functions[rule.endpoint](**req.view_args)
  File "/home/sora8d/Documents/AllVENV/FAIF/lib/python3.9/site-packages/flask_login/utils.py", line 272, in decorated_view
    return func(*args, **kwargs)
TypeError: messaging() got an unexpected keyword argument 'username'
2021-04-02 19:43:26,341 INFO: Ya Server startup [in /home/sora8d/Documents/Code/FAIF/application/__init__.py:76]
